2022-02-20 22:16:43,631 - Start Process CRAW
2022-02-20 22:17:15,348 - Finished Process CRAW
2022-02-20 22:17:46,226 - START craw.py
2022-02-20 22:18:46,236 - Start Process CRAW
2022-02-20 22:19:24,574 - Finished Process CRAW
2022-02-20 22:20:24,582 - Start Process CRAW
2022-02-20 22:20:53,797 - Finished Process CRAW
2022-02-23 09:30:00,116 - START craw.py
2022-02-23 09:31:00,128 - Start Process CRAW
2022-02-23 09:31:02,399 - START craw.py
2022-02-23 09:32:02,410 - Start Process CRAW
2022-02-23 09:32:04,581 - START craw.py
2022-02-23 09:33:04,589 - Start Process CRAW
2022-02-23 09:33:06,529 - START craw.py
2022-02-23 09:33:44,245 - START craw.py
2022-02-23 09:34:06,543 - Start Process CRAW
2022-02-23 09:34:08,897 - START craw.py
2022-02-23 09:34:44,252 - Start Process CRAW
2022-02-23 09:35:08,904 - Start Process CRAW
2022-02-23 09:37:09,079 - START craw.py
2022-02-23 09:38:09,092 - Start Process CRAW
2022-02-23 09:39:05,542 - Finished Process CRAW
2022-02-23 09:40:05,552 - Start Process CRAW
2022-02-23 09:40:59,995 - Finished Process CRAW
2022-02-23 09:41:16,418 - START craw.py
2022-02-23 09:42:00,015 - Start Process CRAW
2022-02-23 09:42:16,421 - Start Process CRAW
2022-02-23 09:42:53,713 - Finished Process CRAW
2022-02-23 09:43:53,720 - Start Process CRAW
2022-02-23 09:44:45,141 - Finished Process CRAW
2022-02-23 09:45:45,144 - Start Process CRAW
2022-02-23 09:46:42,834 - Finished Process CRAW
2022-02-23 09:46:45,932 - START craw.py
2022-02-23 09:47:42,835 - Start Process CRAW
2022-02-23 09:47:45,934 - Start Process CRAW
2022-02-23 09:48:10,543 - START craw.py
2022-02-23 09:48:28,582 - Connection error - could not be pushed to sheet
Traceback (most recent call last):
  File "c:\Users\kalho\Documents\Programmierung\Craw\root.py", line 306, in main
    request = sheet.values().update(spreadsheetId=SAMPLE_SPREADSHEET_ID,
  File "C:\Users\kalho\AppData\Local\Programs\Python\Python310\lib\site-packages\googleapiclient\_helpers.py", line 131, in positional_wrapper
    return wrapped(*args, **kwargs)
  File "C:\Users\kalho\AppData\Local\Programs\Python\Python310\lib\site-packages\googleapiclient\http.py", line 937, in execute
    raise HttpError(resp, content, uri=self.uri)
googleapiclient.errors.HttpError: <HttpError 429 when requesting https://sheets.googleapis.com/v4/spreadsheets/1E5-AezYFSapijKRCwsLUfD16qsq2HTh3f3s-pgGFzNo/values/Kontraktvolumen%21W4?valueInputOption=USER_ENTERED&alt=json returned "Quota exceeded for quota metric 'Write requests' and limit 'Write requests per minute per user' of service 'sheets.googleapis.com' for consumer 'project_number:350535748971'.". Details: "[{'@type': 'type.googleapis.com/google.rpc.ErrorInfo', 'reason': 'RATE_LIMIT_EXCEEDED', 'domain': 'googleapis.com', 'metadata': {'quota_metric': 'sheets.googleapis.com/write_requests', 'service': 'sheets.googleapis.com', 'quota_limit': 'WriteRequestsPerMinutePerUser', 'consumer': 'projects/350535748971'}}]">
2022-02-23 09:48:29,493 - Connection error - could not be pushed to sheet
Traceback (most recent call last):
  File "c:\Users\kalho\Documents\Programmierung\Craw\root.py", line 306, in main
    request = sheet.values().update(spreadsheetId=SAMPLE_SPREADSHEET_ID,
  File "C:\Users\kalho\AppData\Local\Programs\Python\Python310\lib\site-packages\googleapiclient\_helpers.py", line 131, in positional_wrapper
    return wrapped(*args, **kwargs)
  File "C:\Users\kalho\AppData\Local\Programs\Python\Python310\lib\site-packages\googleapiclient\http.py", line 937, in execute
    raise HttpError(resp, content, uri=self.uri)
googleapiclient.errors.HttpError: <HttpError 429 when requesting https://sheets.googleapis.com/v4/spreadsheets/1E5-AezYFSapijKRCwsLUfD16qsq2HTh3f3s-pgGFzNo/values/Kontraktvolumen%21W10?valueInputOption=USER_ENTERED&alt=json returned "Quota exceeded for quota metric 'Write requests' and limit 'Write requests per minute per user' of service 'sheets.googleapis.com' for consumer 'project_number:350535748971'.". Details: "[{'@type': 'type.googleapis.com/google.rpc.ErrorInfo', 'reason': 'RATE_LIMIT_EXCEEDED', 'domain': 'googleapis.com', 'metadata': {'quota_metric': 'sheets.googleapis.com/write_requests', 'service': 'sheets.googleapis.com', 'quota_limit': 'WriteRequestsPerMinutePerUser', 'consumer': 'projects/350535748971'}}]">
2022-02-23 09:48:29,904 - Connection error - could not be pushed to sheet
Traceback (most recent call last):
  File "c:\Users\kalho\Documents\Programmierung\Craw\root.py", line 306, in main
    request = sheet.values().update(spreadsheetId=SAMPLE_SPREADSHEET_ID,
  File "C:\Users\kalho\AppData\Local\Programs\Python\Python310\lib\site-packages\googleapiclient\_helpers.py", line 131, in positional_wrapper
    return wrapped(*args, **kwargs)
  File "C:\Users\kalho\AppData\Local\Programs\Python\Python310\lib\site-packages\googleapiclient\http.py", line 937, in execute
    raise HttpError(resp, content, uri=self.uri)
googleapiclient.errors.HttpError: <HttpError 429 when requesting https://sheets.googleapis.com/v4/spreadsheets/1E5-AezYFSapijKRCwsLUfD16qsq2HTh3f3s-pgGFzNo/values/Kontraktvolumen%21W16?valueInputOption=USER_ENTERED&alt=json returned "Quota exceeded for quota metric 'Write requests' and limit 'Write requests per minute per user' of service 'sheets.googleapis.com' for consumer 'project_number:350535748971'.". Details: "[{'@type': 'type.googleapis.com/google.rpc.ErrorInfo', 'reason': 'RATE_LIMIT_EXCEEDED', 'domain': 'googleapis.com', 'metadata': {'quota_limit': 'WriteRequestsPerMinutePerUser', 'quota_metric': 'sheets.googleapis.com/write_requests', 'service': 'sheets.googleapis.com', 'consumer': 'projects/350535748971'}}]">
2022-02-23 09:48:30,824 - Connection error - could not be pushed to sheet
Traceback (most recent call last):
  File "c:\Users\kalho\Documents\Programmierung\Craw\root.py", line 306, in main
    request = sheet.values().update(spreadsheetId=SAMPLE_SPREADSHEET_ID,
  File "C:\Users\kalho\AppData\Local\Programs\Python\Python310\lib\site-packages\googleapiclient\_helpers.py", line 131, in positional_wrapper
    return wrapped(*args, **kwargs)
  File "C:\Users\kalho\AppData\Local\Programs\Python\Python310\lib\site-packages\googleapiclient\http.py", line 937, in execute
    raise HttpError(resp, content, uri=self.uri)
googleapiclient.errors.HttpError: <HttpError 429 when requesting https://sheets.googleapis.com/v4/spreadsheets/1E5-AezYFSapijKRCwsLUfD16qsq2HTh3f3s-pgGFzNo/values/Kontraktvolumen%21W22?valueInputOption=USER_ENTERED&alt=json returned "Quota exceeded for quota metric 'Write requests' and limit 'Write requests per minute per user' of service 'sheets.googleapis.com' for consumer 'project_number:350535748971'.". Details: "[{'@type': 'type.googleapis.com/google.rpc.ErrorInfo', 'reason': 'RATE_LIMIT_EXCEEDED', 'domain': 'googleapis.com', 'metadata': {'quota_limit': 'WriteRequestsPerMinutePerUser', 'quota_metric': 'sheets.googleapis.com/write_requests', 'service': 'sheets.googleapis.com', 'consumer': 'projects/350535748971'}}]">
2022-02-23 09:48:32,770 - Connection error - could not be pushed to sheet
Traceback (most recent call last):
  File "c:\Users\kalho\Documents\Programmierung\Craw\root.py", line 306, in main
    request = sheet.values().update(spreadsheetId=SAMPLE_SPREADSHEET_ID,
  File "C:\Users\kalho\AppData\Local\Programs\Python\Python310\lib\site-packages\googleapiclient\_helpers.py", line 131, in positional_wrapper
    return wrapped(*args, **kwargs)
  File "C:\Users\kalho\AppData\Local\Programs\Python\Python310\lib\site-packages\googleapiclient\http.py", line 937, in execute
    raise HttpError(resp, content, uri=self.uri)
googleapiclient.errors.HttpError: <HttpError 429 when requesting https://sheets.googleapis.com/v4/spreadsheets/1E5-AezYFSapijKRCwsLUfD16qsq2HTh3f3s-pgGFzNo/values/Kontraktvolumen%21W28?valueInputOption=USER_ENTERED&alt=json returned "Quota exceeded for quota metric 'Write requests' and limit 'Write requests per minute per user' of service 'sheets.googleapis.com' for consumer 'project_number:350535748971'.". Details: "[{'@type': 'type.googleapis.com/google.rpc.ErrorInfo', 'reason': 'RATE_LIMIT_EXCEEDED', 'domain': 'googleapis.com', 'metadata': {'quota_limit': 'WriteRequestsPerMinutePerUser', 'quota_metric': 'sheets.googleapis.com/write_requests', 'service': 'sheets.googleapis.com', 'consumer': 'projects/350535748971'}}]">
2022-02-23 09:48:34,715 - Connection error - could not be pushed to sheet
Traceback (most recent call last):
  File "c:\Users\kalho\Documents\Programmierung\Craw\root.py", line 306, in main
    request = sheet.values().update(spreadsheetId=SAMPLE_SPREADSHEET_ID,
  File "C:\Users\kalho\AppData\Local\Programs\Python\Python310\lib\site-packages\googleapiclient\_helpers.py", line 131, in positional_wrapper
    return wrapped(*args, **kwargs)
  File "C:\Users\kalho\AppData\Local\Programs\Python\Python310\lib\site-packages\googleapiclient\http.py", line 937, in execute
    raise HttpError(resp, content, uri=self.uri)
googleapiclient.errors.HttpError: <HttpError 429 when requesting https://sheets.googleapis.com/v4/spreadsheets/1E5-AezYFSapijKRCwsLUfD16qsq2HTh3f3s-pgGFzNo/values/Kontraktvolumen%21W34?valueInputOption=USER_ENTERED&alt=json returned "Quota exceeded for quota metric 'Write requests' and limit 'Write requests per minute per user' of service 'sheets.googleapis.com' for consumer 'project_number:350535748971'.". Details: "[{'@type': 'type.googleapis.com/google.rpc.ErrorInfo', 'reason': 'RATE_LIMIT_EXCEEDED', 'domain': 'googleapis.com', 'metadata': {'quota_metric': 'sheets.googleapis.com/write_requests', 'service': 'sheets.googleapis.com', 'consumer': 'projects/350535748971', 'quota_limit': 'WriteRequestsPerMinutePerUser'}}]">
2022-02-23 09:48:34,756 - Finished Process CRAW
2022-02-23 09:49:10,547 - Start Process CRAW
2022-02-23 09:49:34,763 - Start Process CRAW
2022-02-23 09:49:36,360 - Connection error - could not be pushed to sheet
Traceback (most recent call last):
  File "c:\Users\kalho\Documents\Programmierung\Craw\root.py", line 306, in main
    request = sheet.values().update(spreadsheetId=SAMPLE_SPREADSHEET_ID,
  File "C:\Users\kalho\AppData\Local\Programs\Python\Python310\lib\site-packages\googleapiclient\_helpers.py", line 131, in positional_wrapper
    return wrapped(*args, **kwargs)
  File "C:\Users\kalho\AppData\Local\Programs\Python\Python310\lib\site-packages\googleapiclient\http.py", line 937, in execute
    raise HttpError(resp, content, uri=self.uri)
googleapiclient.errors.HttpError: <HttpError 429 when requesting https://sheets.googleapis.com/v4/spreadsheets/1E5-AezYFSapijKRCwsLUfD16qsq2HTh3f3s-pgGFzNo/values/Kontraktvolumen%21B4?valueInputOption=USER_ENTERED&alt=json returned "Quota exceeded for quota metric 'Write requests' and limit 'Write requests per minute per user' of service 'sheets.googleapis.com' for consumer 'project_number:350535748971'.". Details: "[{'@type': 'type.googleapis.com/google.rpc.ErrorInfo', 'reason': 'RATE_LIMIT_EXCEEDED', 'domain': 'googleapis.com', 'metadata': {'quota_metric': 'sheets.googleapis.com/write_requests', 'service': 'sheets.googleapis.com', 'consumer': 'projects/350535748971', 'quota_limit': 'WriteRequestsPerMinutePerUser'}}]">
2022-02-23 09:50:26,064 - Finished Process CRAW
2022-02-23 09:51:26,078 - Start Process CRAW
2022-02-23 09:52:16,654 - Finished Process CRAW
2022-02-23 09:53:16,667 - Start Process CRAW
2022-02-23 09:54:07,891 - Finished Process CRAW
2022-02-23 09:55:07,904 - Start Process CRAW
2022-02-23 09:56:04,224 - Finished Process CRAW
2022-02-23 09:57:04,230 - Start Process CRAW
2022-02-23 09:57:51,226 - Finished Process CRAW
2022-02-23 09:58:51,241 - Start Process CRAW
2022-02-23 14:20:04,537 - START craw.py
2022-02-23 14:20:09,551 - Start Process CRAW
2022-02-23 14:20:22,781 - Connection error - could not be pushed to sheet
Traceback (most recent call last):
  File "c:\Users\kalho\Documents\Programmierung\Craw\root.py", line 277, in main
    range=rangeS ,valueInputOption="USER_ENTERED", body={"values": aoa}).execute()
  File "C:\Users\kalho\AppData\Local\Programs\Python\Python310\lib\site-packages\googleapiclient\_helpers.py", line 131, in positional_wrapper
    return wrapped(*args, **kwargs)
  File "C:\Users\kalho\AppData\Local\Programs\Python\Python310\lib\site-packages\googleapiclient\http.py", line 937, in execute
    raise HttpError(resp, content, uri=self.uri)
googleapiclient.errors.HttpError: <HttpError 400 when requesting https://sheets.googleapis.com/v4/spreadsheets/1E5-AezYFSapijKRCwsLUfD16qsq2HTh3f3s-pgGFzNo/values/Kontraktvolumen%21B60?valueInputOption=USER_ENTERED&alt=json returned "Range (Kontraktvolumen!B60) exceeds grid limits. Max rows: 58, max columns: 25". Details: "Range (Kontraktvolumen!B60) exceeds grid limits. Max rows: 58, max columns: 25">
2022-02-23 14:20:24,412 - Connection error - could not be pushed to sheet
Traceback (most recent call last):
  File "c:\Users\kalho\Documents\Programmierung\Craw\root.py", line 277, in main
    range=rangeS ,valueInputOption="USER_ENTERED", body={"values": aoa}).execute()
  File "C:\Users\kalho\AppData\Local\Programs\Python\Python310\lib\site-packages\googleapiclient\_helpers.py", line 131, in positional_wrapper
    return wrapped(*args, **kwargs)
  File "C:\Users\kalho\AppData\Local\Programs\Python\Python310\lib\site-packages\googleapiclient\http.py", line 937, in execute
    raise HttpError(resp, content, uri=self.uri)
googleapiclient.errors.HttpError: <HttpError 400 when requesting https://sheets.googleapis.com/v4/spreadsheets/1E5-AezYFSapijKRCwsLUfD16qsq2HTh3f3s-pgGFzNo/values/Kontraktvolumen%21B68?valueInputOption=USER_ENTERED&alt=json returned "Range (Kontraktvolumen!B68) exceeds grid limits. Max rows: 58, max columns: 25". Details: "Range (Kontraktvolumen!B68) exceeds grid limits. Max rows: 58, max columns: 25">
2022-02-23 14:21:13,157 - Finished Process CRAW
2022-02-24 23:06:03,688 - START craw.py
2022-02-24 23:06:08,727 - Start Process CRAW
2022-02-24 23:06:43,914 - Finished Process CRAW
2022-02-24 23:16:11,822 - START craw.py
2022-02-24 23:16:16,823 - Start Process CRAW
2022-02-24 23:16:52,388 - Finished Process CRAW
2022-02-24 23:19:21,779 - START craw.py
2022-02-24 23:19:26,786 - Start Process CRAW
2022-02-24 23:19:59,954 - Finished Process CRAW
2022-03-07 19:10:49,506 - START craw.py
2022-03-07 19:10:54,510 - Start Process CRAW
2022-03-07 19:11:21,027 - Finished Process CRAW
2022-03-07 19:18:20,883 - START craw.py
2022-03-07 19:18:25,895 - Scheduler started
2022-03-07 19:18:26,046 - Start Process CRAW
2022-03-07 19:18:50,762 - Finished Process CRAW
2022-03-07 19:19:33,054 - START craw.py
2022-03-07 19:19:38,056 - Scheduler started
2022-03-07 19:19:38,199 - Start Process CRAW
2022-03-07 19:20:01,441 - Finished Process CRAW
2022-03-07 19:28:35,795 - START craw.py
2022-03-07 19:28:40,798 - Scheduler started
2022-03-07 19:28:44,115 - Start Process CRAW
2022-03-07 19:29:11,115 - Finished Process CRAW
2022-03-07 19:31:21,271 - START craw.py
2022-03-07 19:31:26,287 - Scheduler started
2022-03-07 19:31:26,435 - Start Process CRAW
2022-03-07 19:31:51,872 - Finished Process CRAW
2022-03-07 19:32:18,039 - START craw.py
2022-03-07 19:32:23,047 - Scheduler started
2022-03-07 19:32:23,257 - Start Process CRAW
2022-03-07 19:32:49,327 - Finished Process CRAW
2022-03-07 19:32:55,966 - Scheduler started
2022-03-07 19:32:56,117 - Start Process CRAW
2022-03-07 19:32:56,145 - Error while getting Updates: Conflict: terminated by other getUpdates request; make sure that only one bot instance is running
2022-03-07 19:33:03,682 - Error while getting Updates: Conflict: terminated by other getUpdates request; make sure that only one bot instance is running
2022-03-07 19:33:11,237 - Error while getting Updates: Conflict: terminated by other getUpdates request; make sure that only one bot instance is running
2022-03-07 19:33:12,980 - Connection error - could not be pushed to sheet
Traceback (most recent call last):
  File "k:\Dokumente\Programmierung\Python\WebScraper\Craw\root.py", line 327, in main
    request = sheet.values().update(spreadsheetId=SAMPLE_SPREADSHEET_ID,
  File "C:\Users\Paul\AppData\Local\Programs\Python\Python39\lib\site-packages\googleapiclient\_helpers.py", line 131, in positional_wrapper
    return wrapped(*args, **kwargs)
  File "C:\Users\Paul\AppData\Local\Programs\Python\Python39\lib\site-packages\googleapiclient\http.py", line 937, in execute
    raise HttpError(resp, content, uri=self.uri)
googleapiclient.errors.HttpError: <HttpError 429 when requesting https://sheets.googleapis.com/v4/spreadsheets/177LVKVaM5a-7tokmpp8anueSLgyBN2DsYvlVA-1CKM8/values/Kontraktvolumen%21Q20?valueInputOption=USER_ENTERED&alt=json returned "Quota exceeded for quota metric 'Write requests' and limit 'Write requests per minute per user' of service 'sheets.googleapis.com' for consumer 'project_number:350535748971'.". Details: "[{'@type': 'type.googleapis.com/google.rpc.ErrorInfo', 'reason': 'RATE_LIMIT_EXCEEDED', 'domain': 'googleapis.com', 'metadata': {'service': 'sheets.googleapis.com', 'quota_limit': 'WriteRequestsPerMinutePerUser', 'quota_metric': 'sheets.googleapis.com/write_requests', 'consumer': 'projects/350535748971'}}]">
2022-03-07 19:33:13,401 - Connection error - could not be pushed to sheet
Traceback (most recent call last):
  File "k:\Dokumente\Programmierung\Python\WebScraper\Craw\root.py", line 327, in main
    request = sheet.values().update(spreadsheetId=SAMPLE_SPREADSHEET_ID,
  File "C:\Users\Paul\AppData\Local\Programs\Python\Python39\lib\site-packages\googleapiclient\_helpers.py", line 131, in positional_wrapper
    return wrapped(*args, **kwargs)
  File "C:\Users\Paul\AppData\Local\Programs\Python\Python39\lib\site-packages\googleapiclient\http.py", line 937, in execute
    raise HttpError(resp, content, uri=self.uri)
googleapiclient.errors.HttpError: <HttpError 429 when requesting https://sheets.googleapis.com/v4/spreadsheets/177LVKVaM5a-7tokmpp8anueSLgyBN2DsYvlVA-1CKM8/values/Kontraktvolumen%21T4?valueInputOption=USER_ENTERED&alt=json returned "Quota exceeded for quota metric 'Write requests' and limit 'Write requests per minute per user' of service 'sheets.googleapis.com' for consumer 'project_number:350535748971'.". Details: "[{'@type': 'type.googleapis.com/google.rpc.ErrorInfo', 'reason': 'RATE_LIMIT_EXCEEDED', 'domain': 'googleapis.com', 'metadata': {'service': 'sheets.googleapis.com', 'quota_limit': 'WriteRequestsPerMinutePerUser', 'quota_metric': 'sheets.googleapis.com/write_requests', 'consumer': 'projects/350535748971'}}]">
2022-03-07 19:33:13,895 - Connection error - could not be pushed to sheet
Traceback (most recent call last):
  File "k:\Dokumente\Programmierung\Python\WebScraper\Craw\root.py", line 327, in main
    request = sheet.values().update(spreadsheetId=SAMPLE_SPREADSHEET_ID,
  File "C:\Users\Paul\AppData\Local\Programs\Python\Python39\lib\site-packages\googleapiclient\_helpers.py", line 131, in positional_wrapper
    return wrapped(*args, **kwargs)
  File "C:\Users\Paul\AppData\Local\Programs\Python\Python39\lib\site-packages\googleapiclient\http.py", line 937, in execute
    raise HttpError(resp, content, uri=self.uri)
googleapiclient.errors.HttpError: <HttpError 429 when requesting https://sheets.googleapis.com/v4/spreadsheets/177LVKVaM5a-7tokmpp8anueSLgyBN2DsYvlVA-1CKM8/values/Kontraktvolumen%21T12?valueInputOption=USER_ENTERED&alt=json returned "Quota exceeded for quota metric 'Write requests' and limit 'Write requests per minute per user' of service 'sheets.googleapis.com' for consumer 'project_number:350535748971'.". Details: "[{'@type': 'type.googleapis.com/google.rpc.ErrorInfo', 'reason': 'RATE_LIMIT_EXCEEDED', 'domain': 'googleapis.com', 'metadata': {'service': 'sheets.googleapis.com', 'quota_limit': 'WriteRequestsPerMinutePerUser', 'quota_metric': 'sheets.googleapis.com/write_requests', 'consumer': 'projects/350535748971'}}]">
2022-03-07 19:33:14,315 - Connection error - could not be pushed to sheet
Traceback (most recent call last):
  File "k:\Dokumente\Programmierung\Python\WebScraper\Craw\root.py", line 327, in main
    request = sheet.values().update(spreadsheetId=SAMPLE_SPREADSHEET_ID,
  File "C:\Users\Paul\AppData\Local\Programs\Python\Python39\lib\site-packages\googleapiclient\_helpers.py", line 131, in positional_wrapper
    return wrapped(*args, **kwargs)
  File "C:\Users\Paul\AppData\Local\Programs\Python\Python39\lib\site-packages\googleapiclient\http.py", line 937, in execute
    raise HttpError(resp, content, uri=self.uri)
googleapiclient.errors.HttpError: <HttpError 429 when requesting https://sheets.googleapis.com/v4/spreadsheets/177LVKVaM5a-7tokmpp8anueSLgyBN2DsYvlVA-1CKM8/values/Kontraktvolumen%21T20?valueInputOption=USER_ENTERED&alt=json returned "Quota exceeded for quota metric 'Write requests' and limit 'Write requests per minute per user' of service 'sheets.googleapis.com' for consumer 'project_number:350535748971'.". Details: "[{'@type': 'type.googleapis.com/google.rpc.ErrorInfo', 'reason': 'RATE_LIMIT_EXCEEDED', 'domain': 'googleapis.com', 'metadata': {'service': 'sheets.googleapis.com', 'quota_limit': 'WriteRequestsPerMinutePerUser', 'quota_metric': 'sheets.googleapis.com/write_requests', 'consumer': 'projects/350535748971'}}]">
2022-03-07 19:33:14,815 - Connection error - could not be pushed to sheet
Traceback (most recent call last):
  File "k:\Dokumente\Programmierung\Python\WebScraper\Craw\root.py", line 327, in main
    request = sheet.values().update(spreadsheetId=SAMPLE_SPREADSHEET_ID,
  File "C:\Users\Paul\AppData\Local\Programs\Python\Python39\lib\site-packages\googleapiclient\_helpers.py", line 131, in positional_wrapper
    return wrapped(*args, **kwargs)
  File "C:\Users\Paul\AppData\Local\Programs\Python\Python39\lib\site-packages\googleapiclient\http.py", line 937, in execute
    raise HttpError(resp, content, uri=self.uri)
googleapiclient.errors.HttpError: <HttpError 429 when requesting https://sheets.googleapis.com/v4/spreadsheets/177LVKVaM5a-7tokmpp8anueSLgyBN2DsYvlVA-1CKM8/values/Kontraktvolumen%21T28?valueInputOption=USER_ENTERED&alt=json returned "Quota exceeded for quota metric 'Write requests' and limit 'Write requests per minute per user' of service 'sheets.googleapis.com' for consumer 'project_number:350535748971'.". Details: "[{'@type': 'type.googleapis.com/google.rpc.ErrorInfo', 'reason': 'RATE_LIMIT_EXCEEDED', 'domain': 'googleapis.com', 'metadata': {'service': 'sheets.googleapis.com', 'quota_limit': 'WriteRequestsPerMinutePerUser', 'quota_metric': 'sheets.googleapis.com/write_requests', 'consumer': 'projects/350535748971'}}]">
2022-03-07 19:33:15,241 - Connection error - could not be pushed to sheet
Traceback (most recent call last):
  File "k:\Dokumente\Programmierung\Python\WebScraper\Craw\root.py", line 327, in main
    request = sheet.values().update(spreadsheetId=SAMPLE_SPREADSHEET_ID,
  File "C:\Users\Paul\AppData\Local\Programs\Python\Python39\lib\site-packages\googleapiclient\_helpers.py", line 131, in positional_wrapper
    return wrapped(*args, **kwargs)
  File "C:\Users\Paul\AppData\Local\Programs\Python\Python39\lib\site-packages\googleapiclient\http.py", line 937, in execute
    raise HttpError(resp, content, uri=self.uri)
googleapiclient.errors.HttpError: <HttpError 429 when requesting https://sheets.googleapis.com/v4/spreadsheets/177LVKVaM5a-7tokmpp8anueSLgyBN2DsYvlVA-1CKM8/values/Kontraktvolumen%21T36?valueInputOption=USER_ENTERED&alt=json returned "Quota exceeded for quota metric 'Write requests' and limit 'Write requests per minute per user' of service 'sheets.googleapis.com' for consumer 'project_number:350535748971'.". Details: "[{'@type': 'type.googleapis.com/google.rpc.ErrorInfo', 'reason': 'RATE_LIMIT_EXCEEDED', 'domain': 'googleapis.com', 'metadata': {'quota_limit': 'WriteRequestsPerMinutePerUser', 'quota_metric': 'sheets.googleapis.com/write_requests', 'service': 'sheets.googleapis.com', 'consumer': 'projects/350535748971'}}]">
2022-03-07 19:33:15,663 - Connection error - could not be pushed to sheet
Traceback (most recent call last):
  File "k:\Dokumente\Programmierung\Python\WebScraper\Craw\root.py", line 327, in main
    request = sheet.values().update(spreadsheetId=SAMPLE_SPREADSHEET_ID,
  File "C:\Users\Paul\AppData\Local\Programs\Python\Python39\lib\site-packages\googleapiclient\_helpers.py", line 131, in positional_wrapper
    return wrapped(*args, **kwargs)
  File "C:\Users\Paul\AppData\Local\Programs\Python\Python39\lib\site-packages\googleapiclient\http.py", line 937, in execute
    raise HttpError(resp, content, uri=self.uri)
googleapiclient.errors.HttpError: <HttpError 429 when requesting https://sheets.googleapis.com/v4/spreadsheets/177LVKVaM5a-7tokmpp8anueSLgyBN2DsYvlVA-1CKM8/values/Kontraktvolumen%21W4?valueInputOption=USER_ENTERED&alt=json returned "Quota exceeded for quota metric 'Write requests' and limit 'Write requests per minute per user' of service 'sheets.googleapis.com' for consumer 'project_number:350535748971'.". Details: "[{'@type': 'type.googleapis.com/google.rpc.ErrorInfo', 'reason': 'RATE_LIMIT_EXCEEDED', 'domain': 'googleapis.com', 'metadata': {'quota_limit': 'WriteRequestsPerMinutePerUser', 'quota_metric': 'sheets.googleapis.com/write_requests', 'service': 'sheets.googleapis.com', 'consumer': 'projects/350535748971'}}]">
2022-03-07 19:33:16,515 - Connection error - could not be pushed to sheet
Traceback (most recent call last):
  File "k:\Dokumente\Programmierung\Python\WebScraper\Craw\root.py", line 327, in main
    request = sheet.values().update(spreadsheetId=SAMPLE_SPREADSHEET_ID,
  File "C:\Users\Paul\AppData\Local\Programs\Python\Python39\lib\site-packages\googleapiclient\_helpers.py", line 131, in positional_wrapper
    return wrapped(*args, **kwargs)
  File "C:\Users\Paul\AppData\Local\Programs\Python\Python39\lib\site-packages\googleapiclient\http.py", line 937, in execute
    raise HttpError(resp, content, uri=self.uri)
googleapiclient.errors.HttpError: <HttpError 429 when requesting https://sheets.googleapis.com/v4/spreadsheets/177LVKVaM5a-7tokmpp8anueSLgyBN2DsYvlVA-1CKM8/values/Kontraktvolumen%21W12?valueInputOption=USER_ENTERED&alt=json returned "Quota exceeded for quota metric 'Write requests' and limit 'Write requests per minute per user' of service 'sheets.googleapis.com' for consumer 'project_number:350535748971'.". Details: "[{'@type': 'type.googleapis.com/google.rpc.ErrorInfo', 'reason': 'RATE_LIMIT_EXCEEDED', 'domain': 'googleapis.com', 'metadata': {'quota_limit': 'WriteRequestsPerMinutePerUser', 'quota_metric': 'sheets.googleapis.com/write_requests', 'service': 'sheets.googleapis.com', 'consumer': 'projects/350535748971'}}]">
2022-03-07 19:33:17,384 - Connection error - could not be pushed to sheet
Traceback (most recent call last):
  File "k:\Dokumente\Programmierung\Python\WebScraper\Craw\root.py", line 327, in main
    request = sheet.values().update(spreadsheetId=SAMPLE_SPREADSHEET_ID,
  File "C:\Users\Paul\AppData\Local\Programs\Python\Python39\lib\site-packages\googleapiclient\_helpers.py", line 131, in positional_wrapper
    return wrapped(*args, **kwargs)
  File "C:\Users\Paul\AppData\Local\Programs\Python\Python39\lib\site-packages\googleapiclient\http.py", line 937, in execute
    raise HttpError(resp, content, uri=self.uri)
googleapiclient.errors.HttpError: <HttpError 429 when requesting https://sheets.googleapis.com/v4/spreadsheets/177LVKVaM5a-7tokmpp8anueSLgyBN2DsYvlVA-1CKM8/values/Kontraktvolumen%21W20?valueInputOption=USER_ENTERED&alt=json returned "Quota exceeded for quota metric 'Write requests' and limit 'Write requests per minute per user' of service 'sheets.googleapis.com' for consumer 'project_number:350535748971'.". Details: "[{'@type': 'type.googleapis.com/google.rpc.ErrorInfo', 'reason': 'RATE_LIMIT_EXCEEDED', 'domain': 'googleapis.com', 'metadata': {'quota_limit': 'WriteRequestsPerMinutePerUser', 'quota_metric': 'sheets.googleapis.com/write_requests', 'service': 'sheets.googleapis.com', 'consumer': 'projects/350535748971'}}]">
2022-03-07 19:33:19,568 - Finished Process CRAW
2022-03-07 19:33:26,266 - Error while getting Updates: Conflict: terminated by other getUpdates request; make sure that only one bot instance is running
2022-03-07 19:33:39,694 - Scheduler started
2022-03-07 19:33:39,817 - Start Process CRAW
2022-03-07 19:33:39,845 - Error while getting Updates: Conflict: terminated by other getUpdates request; make sure that only one bot instance is running
2022-03-07 19:33:40,282 - Connection error - could not be pushed to sheet
Traceback (most recent call last):
  File "k:\Dokumente\Programmierung\Python\WebScraper\Craw\root.py", line 327, in main
    try:
  File "C:\Users\Paul\AppData\Local\Programs\Python\Python39\lib\site-packages\googleapiclient\_helpers.py", line 131, in positional_wrapper
    return wrapped(*args, **kwargs)
  File "C:\Users\Paul\AppData\Local\Programs\Python\Python39\lib\site-packages\googleapiclient\http.py", line 937, in execute
    raise HttpError(resp, content, uri=self.uri)
googleapiclient.errors.HttpError: <HttpError 429 when requesting https://sheets.googleapis.com/v4/spreadsheets/177LVKVaM5a-7tokmpp8anueSLgyBN2DsYvlVA-1CKM8/values/Kontraktvolumen%21B4?valueInputOption=USER_ENTERED&alt=json returned "Quota exceeded for quota metric 'Write requests' and limit 'Write requests per minute per user' of service 'sheets.googleapis.com' for consumer 'project_number:350535748971'.". Details: "[{'@type': 'type.googleapis.com/google.rpc.ErrorInfo', 'reason': 'RATE_LIMIT_EXCEEDED', 'domain': 'googleapis.com', 'metadata': {'service': 'sheets.googleapis.com', 'consumer': 'projects/350535748971', 'quota_limit': 'WriteRequestsPerMinutePerUser', 'quota_metric': 'sheets.googleapis.com/write_requests'}}]">
2022-03-07 19:33:43,193 - Error while getting Updates: Conflict: terminated by other getUpdates request; make sure that only one bot instance is running
2022-03-07 19:33:47,394 - Error while getting Updates: Conflict: terminated by other getUpdates request; make sure that only one bot instance is running
2022-03-07 19:33:50,739 - Error while getting Updates: Conflict: terminated by other getUpdates request; make sure that only one bot instance is running
2022-03-07 19:34:03,005 - Finished Process CRAW
2022-03-07 19:34:05,786 - Error while getting Updates: Conflict: terminated by other getUpdates request; make sure that only one bot instance is running
2022-03-07 19:34:12,830 - Error while getting Updates: Conflict: terminated by other getUpdates request; make sure that only one bot instance is running
2022-03-07 19:34:20,388 - Error while getting Updates: Conflict: terminated by other getUpdates request; make sure that only one bot instance is running
2022-03-07 19:36:06,276 - START craw.py
2022-03-07 19:36:06,276 - Scheduler started
2022-03-07 19:36:11,449 - Start Process CRAW
2022-03-07 19:36:37,342 - Finished Process CRAW
2022-03-07 19:36:46,985 - Start Process CRAW
2022-03-07 19:37:06,906 - Finished Process CRAW
2022-03-07 19:41:54,389 - START craw.py
2022-03-07 19:41:54,390 - Scheduler started
2022-03-07 19:41:59,565 - Start Process CRAW
2022-03-07 19:42:23,008 - START craw.py
2022-03-07 19:42:23,008 - Scheduler started
2022-03-07 19:42:28,144 - Start Process CRAW
2022-03-07 19:47:28,419 - START craw.py
2022-03-07 19:47:28,419 - Scheduler started
2022-03-07 19:47:33,578 - Start Process CRAW
2022-03-07 19:47:53,948 - START craw.py
2022-03-07 19:47:53,948 - Scheduler started
2022-03-07 19:47:54,120 - Error while getting Updates: Conflict: terminated by other getUpdates request; make sure that only one bot instance is running
2022-03-07 19:47:59,099 - Start Process CRAW
2022-03-07 19:48:25,182 - Finished Process CRAW
2022-03-07 19:48:26,892 - Error while getting Updates: Conflict: terminated by other getUpdates request; make sure that only one bot instance is running
2022-03-07 19:49:15,325 - START craw.py
2022-03-07 19:49:15,326 - Scheduler started
2022-03-07 19:49:15,502 - Error while getting Updates: Conflict: terminated by other getUpdates request; make sure that only one bot instance is running
2022-03-07 19:49:20,491 - Start Process CRAW
2022-03-07 19:49:46,841 - Finished Process CRAW
2022-03-07 19:50:20,659 - Start Process CRAW
2022-03-07 19:50:44,518 - Finished Process CRAW
2022-03-07 20:10:07,707 - START craw.py
2022-03-07 20:10:07,708 - Scheduler started
2022-03-07 20:10:12,866 - Start Process CRAW
2022-03-07 20:10:37,675 - Finished Process CRAW
2022-03-07 20:36:50,097 - START craw.py
2022-03-07 20:36:50,098 - Scheduler started
2022-03-07 20:36:55,257 - Start Process CRAW
2022-03-07 20:37:19,896 - Finished Process CRAW
