2022-03-10 21:08:28,702 - START craw.py
2022-03-10 21:08:28,740 - Scheduler started
2022-03-10 21:10:19,408 - START craw.py
2022-03-10 21:10:19,409 - Scheduler started
2022-03-10 21:10:24,829 - Start Process CRAW
2022-03-10 21:11:05,386 - Finished Process CRAW
2022-03-10 21:45:19,086 - Error while getting Updates: urllib3 HTTPError ('Connection aborted.', RemoteDisconnected('Remote end closed connection without response'))
2022-03-10 21:45:38,816 - START craw.py
2022-03-10 21:45:38,817 - Scheduler started
2022-03-10 21:45:44,211 - Start Process CRAW
2022-03-10 21:46:23,655 - Finished Process CRAW
2022-03-10 21:49:49,986 - Start Process CRAW
2022-03-10 21:50:24,878 - Finished Process CRAW
2022-03-10 21:54:10,619 - START craw.py
2022-03-10 21:54:10,655 - Scheduler started
2022-03-10 21:54:16,037 - Start Process CRAW
2022-03-10 21:54:57,400 - Finished Process CRAW
2022-03-10 21:57:40,111 - START craw.py
2022-03-10 21:57:40,112 - Scheduler started
2022-03-10 21:57:45,429 - Start Process CRAW
2022-03-10 21:58:24,761 - Finished Process CRAW
2022-03-10 22:03:01,069 - START craw.py
2022-03-10 22:03:01,070 - Scheduler started
2022-03-10 22:03:06,455 - Start Process CRAW
2022-03-10 22:03:48,038 - Finished Process CRAW
2022-03-10 22:15:25,055 - START craw.py
2022-03-10 22:15:25,057 - Scheduler started
2022-03-10 22:15:30,440 - Start Process CRAW
2022-03-10 22:16:11,564 - Finished Process CRAW
2022-03-10 22:16:30,509 - Scheduler started
2022-03-10 22:16:31,021 - Scheduler started
2022-03-10 22:16:31,535 - Scheduler started
2022-03-10 22:16:32,046 - Scheduler started
2022-03-10 22:16:32,481 - Scheduler started
2022-03-10 22:16:32,865 - Scheduler started
2022-03-10 22:16:33,341 - Scheduler started
2022-03-10 22:16:33,713 - Scheduler started
2022-03-10 22:16:34,196 - Scheduler started
2022-03-10 22:16:34,708 - Scheduler started
2022-03-10 22:16:35,221 - Scheduler started
2022-03-10 22:16:35,729 - Error while getting Updates: Conflict: terminated by other getUpdates request; make sure that only one bot instance is running
2022-03-10 22:16:35,923 - Start Process CRAW
2022-03-10 22:16:36,441 - Start Process CRAW
2022-03-10 22:16:36,957 - Start Process CRAW
2022-03-10 22:16:37,059 - Connection error - could not be pushed to sheet
Traceback (most recent call last):
  File "c:\Users\kalho\Documents\Programmierung\Craw\root.py", line 345, in main
    range=rangeS ,valueInputOption="USER_ENTERED", body={"values": aoa}).execute()
  File "C:\Users\kalho\AppData\Local\Programs\Python\Python310\lib\site-packages\googleapiclient\_helpers.py", line 131, in positional_wrapper
    return wrapped(*args, **kwargs)
  File "C:\Users\kalho\AppData\Local\Programs\Python\Python310\lib\site-packages\googleapiclient\http.py", line 922, in execute
    resp, content = _retry_request(
  File "C:\Users\kalho\AppData\Local\Programs\Python\Python310\lib\site-packages\googleapiclient\http.py", line 221, in _retry_request
    raise exception
  File "C:\Users\kalho\AppData\Local\Programs\Python\Python310\lib\site-packages\googleapiclient\http.py", line 190, in _retry_request
    resp, content = http.request(uri, method, *args, **kwargs)
  File "C:\Users\kalho\AppData\Local\Programs\Python\Python310\lib\site-packages\google_auth_httplib2.py", line 218, in request
    response, content = self.http.request(
  File "C:\Users\kalho\AppData\Local\Programs\Python\Python310\lib\site-packages\httplib2\__init__.py", line 1701, in request
    (response, content) = self._request(
  File "C:\Users\kalho\AppData\Local\Programs\Python\Python310\lib\site-packages\httplib2\__init__.py", line 1421, in _request
    (response, content) = self._conn_request(conn, request_uri, method, body, headers)
  File "C:\Users\kalho\AppData\Local\Programs\Python\Python310\lib\site-packages\httplib2\__init__.py", line 1373, in _conn_request
    response = conn.getresponse()
  File "C:\Users\kalho\AppData\Local\Programs\Python\Python310\lib\http\client.py", line 1374, in getresponse
    response.begin()
  File "C:\Users\kalho\AppData\Local\Programs\Python\Python310\lib\http\client.py", line 318, in begin
    version, status, reason = self._read_status()
  File "C:\Users\kalho\AppData\Local\Programs\Python\Python310\lib\http\client.py", line 279, in _read_status
    line = str(self.fp.readline(_MAXLINE + 1), "iso-8859-1")
  File "C:\Users\kalho\AppData\Local\Programs\Python\Python310\lib\socket.py", line 705, in readinto
    return self._sock.recv_into(b)
  File "C:\Users\kalho\AppData\Local\Programs\Python\Python310\lib\ssl.py", line 1273, in recv_into
    return self.read(nbytes, buffer)
  File "C:\Users\kalho\AppData\Local\Programs\Python\Python310\lib\ssl.py", line 1129, in read
    return self._sslobj.read(len, buffer)
ssl.SSLError: [SSL: WRONG_VERSION_NUMBER] wrong version number (_ssl.c:2536)
2022-03-10 22:16:37,060 - Connection error - could not be pushed to sheet
Traceback (most recent call last):
  File "c:\Users\kalho\Documents\Programmierung\Craw\root.py", line 345, in main
    range=rangeS ,valueInputOption="USER_ENTERED", body={"values": aoa}).execute()
  File "C:\Users\kalho\AppData\Local\Programs\Python\Python310\lib\site-packages\googleapiclient\_helpers.py", line 131, in positional_wrapper
    return wrapped(*args, **kwargs)
  File "C:\Users\kalho\AppData\Local\Programs\Python\Python310\lib\site-packages\googleapiclient\http.py", line 922, in execute
    resp, content = _retry_request(
  File "C:\Users\kalho\AppData\Local\Programs\Python\Python310\lib\site-packages\googleapiclient\http.py", line 221, in _retry_request
    raise exception
  File "C:\Users\kalho\AppData\Local\Programs\Python\Python310\lib\site-packages\googleapiclient\http.py", line 190, in _retry_request
    resp, content = http.request(uri, method, *args, **kwargs)
  File "C:\Users\kalho\AppData\Local\Programs\Python\Python310\lib\site-packages\google_auth_httplib2.py", line 218, in request
    response, content = self.http.request(
  File "C:\Users\kalho\AppData\Local\Programs\Python\Python310\lib\site-packages\httplib2\__init__.py", line 1701, in request
    (response, content) = self._request(
  File "C:\Users\kalho\AppData\Local\Programs\Python\Python310\lib\site-packages\httplib2\__init__.py", line 1421, in _request
    (response, content) = self._conn_request(conn, request_uri, method, body, headers)
  File "C:\Users\kalho\AppData\Local\Programs\Python\Python310\lib\site-packages\httplib2\__init__.py", line 1373, in _conn_request
    response = conn.getresponse()
  File "C:\Users\kalho\AppData\Local\Programs\Python\Python310\lib\http\client.py", line 1374, in getresponse
    response.begin()
  File "C:\Users\kalho\AppData\Local\Programs\Python\Python310\lib\http\client.py", line 318, in begin
    version, status, reason = self._read_status()
  File "C:\Users\kalho\AppData\Local\Programs\Python\Python310\lib\http\client.py", line 279, in _read_status
    line = str(self.fp.readline(_MAXLINE + 1), "iso-8859-1")
  File "C:\Users\kalho\AppData\Local\Programs\Python\Python310\lib\socket.py", line 705, in readinto
    return self._sock.recv_into(b)
  File "C:\Users\kalho\AppData\Local\Programs\Python\Python310\lib\ssl.py", line 1273, in recv_into
    return self.read(nbytes, buffer)
  File "C:\Users\kalho\AppData\Local\Programs\Python\Python310\lib\ssl.py", line 1129, in read
    return self._sslobj.read(len, buffer)
ssl.SSLError: [SSL: WRONG_VERSION_NUMBER] wrong version number (_ssl.c:2536)
2022-03-10 22:16:37,456 - Start Process CRAW
2022-03-10 22:16:37,765 - Start Process CRAW
2022-03-10 22:16:38,292 - Start Process CRAW
2022-03-10 22:16:38,695 - Start Process CRAW
2022-03-10 22:16:38,802 - Error while getting Updates: Conflict: terminated by other getUpdates request; make sure that only one bot instance is running
2022-03-10 22:16:39,099 - Start Process CRAW
2022-03-10 22:16:39,116 - Error while getting Updates: Conflict: terminated by other getUpdates request; make sure that only one bot instance is running
2022-03-10 22:16:39,612 - Start Process CRAW
2022-03-10 22:16:39,630 - Error while getting Updates: Conflict: terminated by other getUpdates request; make sure that only one bot instance is running
2022-03-10 22:16:40,090 - Error while getting Updates: Conflict: terminated by other getUpdates request; make sure that only one bot instance is running
2022-03-10 22:16:40,126 - Start Process CRAW
2022-03-10 22:16:40,557 - Error while getting Updates: Conflict: terminated by other getUpdates request; make sure that only one bot instance is running
2022-03-10 22:16:40,639 - Start Process CRAW
2022-03-10 22:16:40,914 - Error while getting Updates: Conflict: terminated by other getUpdates request; make sure that only one bot instance is running
2022-03-10 22:16:41,463 - Error while getting Updates: Conflict: terminated by other getUpdates request; make sure that only one bot instance is running
2022-03-10 22:16:42,251 - Error while getting Updates: Conflict: terminated by other getUpdates request; make sure that only one bot instance is running
2022-03-10 22:16:42,795 - Error while getting Updates: Conflict: terminated by other getUpdates request; make sure that only one bot instance is running
2022-03-10 22:16:43,306 - Error while getting Updates: Conflict: terminated by other getUpdates request; make sure that only one bot instance is running
2022-03-10 22:16:43,307 - Error while getting Updates: Conflict: terminated by other getUpdates request; make sure that only one bot instance is running
2022-03-10 22:16:46,360 - Error while getting Updates: Conflict: terminated by other getUpdates request; make sure that only one bot instance is running
2022-03-10 22:16:49,759 - Error while getting Updates: Conflict: terminated by other getUpdates request; make sure that only one bot instance is running
2022-03-10 22:16:49,820 - Error while getting Updates: Conflict: terminated by other getUpdates request; make sure that only one bot instance is running
2022-03-10 22:16:50,270 - Error while getting Updates: Conflict: terminated by other getUpdates request; make sure that only one bot instance is running
2022-03-10 22:16:50,681 - Error while getting Updates: Conflict: terminated by other getUpdates request; make sure that only one bot instance is running
2022-03-10 22:18:04,773 - START craw.py
2022-03-10 22:18:04,775 - Scheduler started
2022-03-10 22:18:10,236 - Start Process CRAW
2022-03-10 22:18:50,082 - Finished Process CRAW
2022-03-10 22:31:02,537 - START craw.py
2022-03-10 22:31:02,539 - Scheduler started
2022-03-10 22:31:07,960 - Start Process CRAW
2022-03-10 22:31:47,588 - Finished Process CRAW
2022-03-10 22:35:37,070 - START craw.py
2022-03-10 22:35:37,072 - Scheduler started
2022-03-10 22:35:42,601 - Start Process CRAW
2022-03-10 22:36:22,654 - Finished Process CRAW
2022-03-10 22:37:07,302 - START craw.py
2022-03-10 22:37:07,304 - Scheduler started
2022-03-10 22:37:12,827 - Start Process CRAW
2022-03-10 22:37:53,790 - Finished Process CRAW
2022-03-10 22:38:58,917 - START craw.py
2022-03-10 22:38:58,948 - Scheduler started
2022-03-10 22:39:04,328 - Start Process CRAW
2022-03-10 22:39:43,363 - Finished Process CRAW
2022-03-10 22:39:46,942 - Start Process CRAW
2022-03-10 22:40:21,249 - Finished Process CRAW
